<mujoco model="3-DOF Robot Arm with Auto Reset">
  <compiler angle="radian" inertiafromgeom="true"/>
  <option timestep="0.005" gravity="0 0 -9.81"/>
  <visual>
    <global azimuth="30" elevation="-25"/>  <!-- 清晰3D视角 -->
  </visual>
  <asset>
    <material name="red" rgba="0.8 0.2 0.2 1"/>
    <material name="yellow" rgba="0.8 0.7 0.2 1"/>
    <material name="gray" rgba="0.5 0.5 0.5 1"/>
    <material name="blue" rgba="0.2 0.4 0.8 1"/>
    <material name="green" rgba="0.2 0.8 0.2 1"/>
  </asset>

  <!-- 世界体定义 -->
  <worldbody>
    <!-- 固定监控相机 -->
    <camera name="monitor_camera" pos="1.8 1.8 1.2" xyaxes="1 0 0 0 1 0"/>
    <!-- 工作平台 -->
    <geom name="workbench" type="plane" size="2 2 0.1" pos="0 0 -0.05" material="gray"/>
    <!-- 待抓取目标：蓝色球体（易抓取，不易滚落） -->
    <body name="target_ball" pos="0.9 0.6 0.0">
      <geom name="target_geom" type="sphere" size="0.08" pos="0 0 0" material="blue"/>
      <joint name="target_joint" type="free"/>
    </body>
    <!-- 目标放置区域：绿色圆形标记 -->
    <geom name="place_area" type="cylinder" size="0.15 0.01" pos="-0.9 0.6 0.0" material="green"/>
    <!-- 3自由度机械臂 -->
    <body name="robot_base" pos="0 0 0.0">
      <geom name="base_geom" type="cylinder" size="0.18 0.1" pos="0 0 0" material="yellow"/>
      <joint name="base_joint" type="free"/>

      <!-- 关节1：基座旋转（Z轴） -->
      <body name="arm_1" pos="0 0 0.1">
        <geom name="arm1_geom" type="cylinder" size="0.08 0.6" pos="0 0 0.3" material="yellow"/>
        <joint name="joint1_rotate" type="hinge" axis="0 0 1" pos="0 0 0" range="-3.14 3.14" damping="0.03"/>

        <!-- 关节2：大臂俯仰（Y轴） -->
        <body name="arm_2" pos="0 0 0.6">
          <geom name="arm2_geom" type="cylinder" size="0.07 0.5" pos="0 0 0.25" material="yellow"/>
          <joint name="joint2_pitch" type="hinge" axis="0 1 0" pos="0 0 0" range="-1.5 1.5" damping="0.03"/>

          <!-- 关节3：小臂伸缩（X轴） -->
          <body name="arm_3" pos="0 0 0.5">
            <geom name="arm3_geom" type="cylinder" size="0.06 0.4" pos="0.2 0 0" material="yellow"/>
            <joint name="joint3_telescope" type="slide" axis="1 0 0" pos="0 0 0" range="0 0.4" damping="0.03"/>

            <!-- 平行夹爪 -->
            <body name="gripper_base" pos="0.4 0 0">
              <geom name="gripper_base_geom" type="box" size="0.07 0.07 0.07" pos="0 0 0" material="red"/>

              <!-- 左夹爪 -->
              <body name="gripper_left" pos="0 0.07 0">
                <geom name="gripper_left_geom" type="box" size="0.05 0.04 0.05" pos="0 0 0" material="red"/>
                <joint name="gripper_left_joint" type="hinge" axis="0 0 1" pos="0 -0.07 0" range="-0.4 0" damping="0.02"/>
              </body>

              <!-- 右夹爪 -->
              <body name="gripper_right" pos="0 -0.07 0">
                <geom name="gripper_right_geom" type="box" size="0.05 0.04 0.05" pos="0 0 0" material="red"/>
                <joint name="gripper_right_joint" type="hinge" axis="0 0 1" pos="0 0.07 0" range="0 0.4" damping="0.02"/>
              </body>
            </body>
          </body>
        </body>
      </body>
    </body>
  </worldbody>

  <!-- 执行器配置（MuJoCo 3.4.0 完全兼容） -->
  <actuator>
    <!-- 关节位置控制（高精度） -->
    <position name="joint1_act" joint="joint1_rotate" kp="1100" kv="100"/>
    <position name="joint2_act" joint="joint2_pitch" kp="1100" kv="100"/>
    <position name="joint3_act" joint="joint3_telescope" kp="1100" kv="100"/>

    <!-- 夹爪速度控制（软接触，防损坏） -->
    <velocity name="gripper_left_act" joint="gripper_left_joint" kv="40" ctrlrange="-0.3 0"/>
    <velocity name="gripper_right_act" joint="gripper_right_joint" kv="40" ctrlrange="0 0.3"/>
  </actuator>
</mujoco>