<?xml version="1.0" encoding="utf-8"?>
<mujoco model="iiwa14_with_three_finger_gripper">
  <compiler angle="radian" autolimits="true"/>

  <option integrator="implicitfast"/>

  <default>
    <default class="iiwa">
      <material specular="0.5" shininess="0.25"/>
      <joint axis="0 0 1" damping="0.1"/>
      <general gaintype="fixed" biastype="affine" gainprm="2000" biasprm="0 -2000 -200"/>
      <default class="joint1">
        <joint range="-2.96706 2.96706"/>
        <general ctrlrange="-2.96706 2.96706"/>
        <default class="joint2">
          <joint range="-2.0944 2.0944"/>
          <general ctrlrange="-2.0944 2.0944"/>
        </default>
      </default>
      <default class="joint3">
        <joint range="-3.05433 3.05433"/>
        <general ctrlrange="-3.05433 3.05433"/>
      </default>
      <default class="visual">
        <geom type="capsule" size="0.05" contype="0" conaffinity="0" group="2" material="gray"/>
      </default>
      <default class="collision">
        <geom group="3"/>
      </default>
      <site size="0.001" rgba="1 0 0 1" group="4"/>
      
      <!-- Gripper defaults -->
      <default class="gripper">
        <joint damping="0.5" frictionloss="0.1"/>
        <default class="finger_joint">
          <joint range="0 0.12" axis="0 1 0"/>
          <general ctrlrange="0 0.12"/>
        </default>
        <default class="finger_bend_joint">
          <joint range="-1.57 1.57" axis="1 0 0" damping="0.1"/>
          <general ctrlrange="-1.57 1.57"/>
        </default>
      </default>
      <default class="gripper_visual">
        <geom type="box" size="0.02 0.02 0.04" contype="0" conaffinity="0" group="2" material="orange"/>
      </default>
      <default class="gripper_collision">
        <geom group="3"/>
      </default>
    </default>
  </default>

  <asset>
    <texture name="skybox" type="skybox" builtin="gradient" rgb1="0.3 0.5 0.7" rgb2="0 0 0" width="512" height="512"/>
    <texture name="grid" type="2d" builtin="checker" rgb1="0.1 0.2 0.3" rgb2="0.2 0.3 0.4" width="512" height="512" mark="edge" markrgb="0.8 0.8 0.8"/>
    <material name="grid" texture="grid" texrepeat="1 1" texuniform="true" reflectance="0.2"/>
    <material class="iiwa" name="gray" rgba="0.4 0.4 0.4 1"/>
    <material class="iiwa" name="light_gray" rgba="0.6 0.6 0.6 1"/>
    <material class="iiwa" name="black" rgba="0 0 0 1"/>
    <material class="iiwa" name="orange" rgba="1 0.423529 0.0392157 1"/>
  </asset>

  <worldbody>
    <light name="top" pos="0 0 2" mode="trackcom"/>
    <geom name="floor" pos="0 0 -0.01" size="1 1 0.01" type="plane" material="grid"/>
    <body name="base" childclass="iiwa">
      <inertial mass="5" pos="-0.1 0 0.07" diaginertia="0.05 0.06 0.03"/>
      <geom class="visual" type="cylinder" size="0.1 0.1"/>
      <geom class="collision" size="0.12" pos="0 0 0.03"/>
      <geom class="collision" size="0.08" pos="-0.08 0 0.103"/>
      <geom class="collision" size="0.08" pos="-0.08 0 0.04"/>
      <geom class="collision" size="0.1" pos="0 0 0.14"/>
      <body name="link1" pos="0 0 0.1575">
        <inertial mass="5.76" pos="0 -0.03 0.12" diaginertia="0.0333 0.033 0.0123"/>
        <joint name="joint1" class="joint1"/>
        <geom class="visual" type="capsule" size="0.05 0.1"/>
        <geom class="collision" size="0.08" pos="0 0 -0.0005"/>
        <geom class="collision" size="0.075" pos="0.01 -0.025 0.0425"/>
        <geom class="collision" size="0.075" pos="-0.01 -0.025 0.0425"/>
        <geom class="collision" size="0.07" pos="0.01 -0.045 0.1025"/>
        <geom class="collision" size="0.07" pos="-0.01 -0.045 0.1025"/>
        <body name="link2" pos="0 0 0.2025" quat="0 0 1 1">
          <inertial mass="6.35" pos="0.0003 0.059 0.042" diaginertia="0.0305 0.0304 0.011" quat="0 0 1 1"/>
          <joint name="joint2" class="joint2"/>
          <geom class="visual" type="capsule" size="0.05 0.1" material="orange"/>
          <geom class="collision" size="0.095" pos="0 0 -0.01"/>
          <geom class="collision" size="0.09" pos="0 0 0.045"/>
          <geom class="collision" size="0.07" pos="-0.01 0.04 0.054"/>
          <geom class="collision" size="0.065" pos="-0.01 0.09 0.04"/>
          <geom class="collision" size="0.065" pos="-0.01 0.13 0.02"/>
          <geom class="collision" size="0.07" pos="0.01 0.04 0.054"/>
          <geom class="collision" size="0.065" pos="0.01 0.09 0.04"/>
          <geom class="collision" size="0.065" pos="0.01 0.13 0.02"/>
          <geom class="collision" size="0.075" pos="0 0.18 0"/>
          <body name="link3" pos="0 0.2045 0" quat="0 0 1 1">
            <inertial mass="3.5" pos="0 0.03 0.13" diaginertia="0.025 0.0238 0.0076"/>
            <joint name="joint3" class="joint1"/>
            <geom class="visual" type="capsule" size="0.05 0.1"/>
            <geom class="collision" size="0.075" pos="0 0 0.0355"/>
            <geom class="collision" size="0.06" pos="0.01 0.023 0.0855"/>
            <geom class="collision" size="0.055" pos="0.01 0.048 0.1255"/>
            <geom class="collision" size="0.06" pos="0.01 0.056 0.1755"/>
            <geom class="collision" size="0.06" pos="-0.01 0.023 0.0855"/>
            <geom class="collision" size="0.055" pos="-0.01 0.048 0.1255"/>
            <geom class="collision" size="0.06" pos="-0.01 0.056 0.1755"/>
            <geom class="collision" size="0.075" pos="0 0.045 0.2155"/>
            <geom class="collision" size="0.075" pos="0 0 0.2155"/>
            <body name="link4" pos="0 0 0.2155" quat="1 1 0 0">
              <inertial mass="3.5" pos="0 0.067 0.034" diaginertia="0.017 0.0164 0.006" quat="1 1 0 0"/>
              <joint name="joint4" class="joint2"/>
              <geom class="visual" type="capsule" size="0.05 0.1" material="orange"/>
              <geom class="collision" size="0.078" pos="0 0.01 0.046"/>
              <geom class="collision" size="0.06" pos="0.01 0.06 0.052"/>
              <geom class="collision" size="0.065" pos="0.01 0.12 0.034"/>
              <geom class="collision" size="0.06" pos="-0.01 0.06 0.052"/>
              <geom class="collision" size="0.065" pos="-0.01 0.12 0.034"/>
              <geom class="collision" size="0.075" pos="0 0.184 0"/>
              <body name="link5" pos="0 0.1845 0" quat="0 0 1 1">
                <inertial mass="3.5" pos="0.0001 0.021 0.076" diaginertia="0.01 0.0087 0.00449"/>
                <joint name="joint5" class="joint1"/>
                <geom class="visual" type="capsule" size="0.05 0.1"/>
                <geom class="collision" size="0.075" pos="0 0 0.0335"/>
                <geom class="collision" size="0.05" pos="-0.012 0.031 0.0755"/>
                <geom class="collision" size="0.05" pos="0.012 0.031 0.0755"/>
                <geom class="collision" size="0.04" pos="-0.012 0.06 0.1155"/>
                <geom class="collision" size="0.04" pos="0.012 0.06 0.1155"/>
                <geom class="collision" size="0.04" pos="-0.01 0.065 0.1655"/>
                <geom class="collision" size="0.04" pos="0.01 0.065 0.1655"/>
                <geom class="collision" size="0.035" pos="-0.012 0.065 0.1855"/>
                <geom class="collision" size="0.035" pos="0.012 0.065 0.1855"/>
                <body name="link6" pos="0 0 0.2155" quat="1 1 0 0">
                  <inertial mass="1.8" pos="0 0.0006 0.0004" diaginertia="0.0049 0.0047 0.0036" quat="1 1 0 0"/>
                  <joint name="joint6" class="joint2"/>
                  <geom class="visual" type="capsule" size="0.05 0.1" material="orange"/>
                  <geom class="collision" size="0.055" pos="0 0 -0.059"/>
                  <geom class="collision" size="0.065" pos="0 -0.03 0.011"/>
                  <geom class="collision" size="0.08"/>
                  <body name="link7" pos="0 0.081 0" quat="0 0 1 1">
                    <inertial mass="1.2" pos="0 0 0.02" diaginertia="0.001 0.001 0.001"/>
                    <joint name="joint7" class="joint3"/>
                    <geom class="visual" type="capsule" size="0.05 0.05"/>
                    <geom class="collision" size="0.06" pos="0 0 0.001"/>
                    <site pos="0 0 0.045" name="attachment_site"/>
                    
                    <!-- 三指夹爪 -->
                    <body name="gripper_base" pos="0 0 0.045">
                      <inertial mass="0.1" pos="0 0 0" diaginertia="0.001 0.001 0.001"/>
                      <geom class="visual" type="box" size="0.02 0.02 0.02" material="black"/>
                      <geom class="collision" type="box" size="0.02 0.02 0.02"/>
                      
                      <!-- 手指1 -->
                      <body name="finger1_base" pos="0.04 0 0.02" euler="0 0 0">
                        <inertial mass="0.005" pos="0 0 0.02" diaginertia="0.0001 0.0001 0.0001"/>
                        <joint name="finger_joint1" class="finger_joint"/>
                        <geom class="gripper_visual" pos="0 0 0.02" material="orange"/>
                        <geom class="gripper_collision" type="box" size="0.02 0.02 0.02"/>
                        
                        <!-- 连接球体 -->
                        <body name="finger1_link" pos="0 0 0.045">
                          <inertial mass="0.001" pos="0 0 0" diaginertia="0.00001 0.00001 0.00001"/>
                          <geom type="sphere" size="0.025" pos="0 0 0" material="black" contype="0" conaffinity="0" group="2"/>
                          <geom type="sphere" size="0.025" pos="0 0 0" group="3"/>
                          
                          <!-- 手指第一节 -->
                          <body name="finger1_tip" pos="0 0 0.05">
                            <inertial mass="0.005" pos="0 0 0.02" diaginertia="0.0001 0.0001 0.0001"/>
                            <joint name="finger1_bend" class="finger_bend_joint"/>
                            <geom class="gripper_visual" pos="0 0 0.02" material="orange"/>
                            <geom class="gripper_collision" type="box" size="0.02 0.02 0.02"/>
                          </body>
                        </body>
                      </body>
                      
                      <!-- 手指2 -->
                      <body name="finger2_base" pos="-0.02 0.0346 0.02" euler="0 0 2.0944"> <!-- 120度 -->
                        <inertial mass="0.005" pos="0 0 0.02" diaginertia="0.0001 0.0001 0.0001"/>
                        <joint name="finger_joint2" class="finger_joint"/>
                        <geom class="gripper_visual" pos="0 0 0.02" material="orange"/>
                        <geom class="gripper_collision" type="box" size="0.02 0.02 0.02"/>
                        
                        <!-- 连接球体 -->
                        <body name="finger2_link" pos="0 0 0.045">
                          <inertial mass="0.001" pos="0 0 0" diaginertia="0.00001 0.00001 0.00001"/>
                          <geom type="sphere" size="0.025" pos="0 0 0" material="black" contype="0" conaffinity="0" group="2"/>
                          <geom type="sphere" size="0.025" pos="0 0 0" group="3"/>
                          
                          <!-- 手指第二节 -->
                          <body name="finger2_tip" pos="0 0 0.05">
                            <inertial mass="0.005" pos="0 0 0.02" diaginertia="0.0001 0.0001 0.0001"/>
                            <joint name="finger2_bend" class="finger_bend_joint"/>
                            <geom class="gripper_visual" pos="0 0 0.02" material="orange"/>
                            <geom class="gripper_collision" type="box" size="0.02 0.02 0.02"/>
                          </body>
                        </body>
                      </body>
                      
                      <!-- 手指3 -->
                      <body name="finger3_base" pos="-0.02 -0.0346 0.02" euler="0 0 4.1888"> <!-- 240度 -->
                        <inertial mass="0.005" pos="0 0 0.02" diaginertia="0.0001 0.0001 0.0001"/>
                        <joint name="finger_joint3" class="finger_joint"/>
                        <geom class="gripper_visual" pos="0 0 0.02" material="orange"/>
                        <geom class="gripper_collision" type="box" size="0.02 0.02 0.02"/>
                        
                        <!-- 连接球体 -->
                        <body name="finger3_link" pos="0 0 0.045">
                          <inertial mass="0.001" pos="0 0 0" diaginertia="0.00001 0.00001 0.00001"/>
                          <geom type="sphere" size="0.025" pos="0 0 0" material="black" contype="0" conaffinity="0" group="2"/>
                          <geom type="sphere" size="0.025" pos="0 0 0" group="3"/>
                          
                          <!-- 手指第三节 -->
                          <body name="finger3_tip" pos="0 0 0.05">
                            <inertial mass="0.005" pos="0 0 0.02" diaginertia="0.0001 0.0001 0.0001"/>
                            <joint name="finger3_bend" class="finger_bend_joint"/>
                            <geom class="gripper_visual" pos="0 0 0.02" material="orange"/>
                            <geom class="gripper_collision" type="box" size="0.02 0.02 0.02"/>
                          </body>
                        </body>
                      </body>
                    </body>
                  </body>
                </body>
              </body>
            </body>
          </body>
        </body>
      </body>
    </body>
  </worldbody>

  <contact>
    <exclude body1="base" body2="link1"/>
    <exclude body1="base" body2="link2"/>
    <exclude body1="base" body2="link3"/>
    <exclude body1="link1" body2="link3"/>
    <exclude body1="link3" body2="link5"/>
    <exclude body1="link4" body2="link7"/>
    <exclude body1="link5" body2="link7"/>
  </contact>

  <actuator>
    <general name="actuator1" joint="joint1" class="joint1"/>
    <general name="actuator2" joint="joint2" class="joint2"/>
    <general name="actuator3" joint="joint3" class="joint1"/>
    <general name="actuator4" joint="joint4" class="joint2"/>
    <general name="actuator5" joint="joint5" class="joint1"/>
    <general name="actuator6" joint="joint6" class="joint2"/>
    <general name="actuator7" joint="joint7" class="joint3"/>
    
    <!-- 夹爪驱动 -->
    <general name="gripper_actuator1" joint="finger_joint1" class="finger_joint"/>
    <general name="gripper_actuator2" joint="finger_joint2" class="finger_joint"/>
    <general name="gripper_actuator3" joint="finger_joint3" class="finger_joint"/>
    
    <!-- 弯曲关节驱动 -->
    <general name="finger1_bend_actuator" joint="finger1_bend" class="finger_bend_joint"/>
    <general name="finger2_bend_actuator" joint="finger2_bend" class="finger_bend_joint"/>
    <general name="finger3_bend_actuator" joint="finger3_bend" class="finger_bend_joint"/>
  </actuator>

  <keyframe>
    <key name="home" qpos="0 0.785398 0 -1.5708 0 0 0 0 0 0 0 0 0" ctrl="0 0.785398 0 -1.5708 0 0 0 0 0 0 0 0 0"/>
  </keyframe>
</mujoco>