<mujoco model="simple_humanoid">
  <compiler angle="radian" inertiafromgeom="true"/>
  <option timestep="0.005" gravity="0 0 -9.81" iterations="100" tolerance="1e-6"/>
  <visual>
    <global azimuth="135" elevation="-30" perspective="0.01"/>
  </visual>
  <worldbody>
    <light pos="0 0 5" dir="0 0 -1" diffuse="1 1 1" specular="0.1 0.1 0.1"/>
    <geom name="floor" type="plane" size="10 10 0.1" pos="0 0 0" rgba="0.8 0.8 0.8 1" condim="3"/>

    <!-- 机器人主体 -->
    <body name="pelvis" pos="0 0 1.0">
      <joint name="root" type="free"/>
      <geom name="pelvis_geom" type="capsule" size="0.1" fromto="0 0 0 0 0 0.2" rgba="0.5 0.5 0.9 1" mass="5"/>

      <body name="torso" pos="0 0 0.2">
        <geom name="torso_geom" type="capsule" size="0.1" fromto="0 0 0 0 0 0.3" rgba="0.5 0.5 0.9 1" mass="8"/>

        <body name="head" pos="0 0 0.3">
          <geom name="head_geom" type="sphere" size="0.15" pos="0 0 0" rgba="0.8 0.5 0.5 1" mass="3"/>
        </body>

        <!-- 左手臂 -->
        <body name="left_arm" pos="0.15 0 0.15">
          <joint name="left_shoulder" type="hinge" axis="1 0 0" range="-1.57 1.57"/>
          <geom name="left_upper_arm" type="capsule" size="0.05" fromto="0 0 0 0 0 0.2" rgba="0.5 0.9 0.5 1" mass="1"/>

          <body name="left_forearm" pos="0 0 0.2">
            <joint name="left_elbow" type="hinge" axis="1 0 0" range="-1.57 0"/>
            <geom name="left_forearm_geom" type="capsule" size="0.04" fromto="0 0 0 0 0 0.2" rgba="0.5 0.9 0.5 1" mass="0.5"/>
          </body>
        </body>

        <!-- 右手臂 -->
        <body name="right_arm" pos="-0.15 0 0.15">
          <joint name="right_shoulder" type="hinge" axis="1 0 0" range="-1.57 1.57"/>
          <geom name="right_upper_arm" type="capsule" size="0.05" fromto="0 0 0 0 0 0.2" rgba="0.5 0.9 0.5 1" mass="1"/>

          <body name="right_forearm" pos="0 0 0.2">
            <joint name="right_elbow" type="hinge" axis="1 0 0" range="-1.57 0"/>
            <geom name="right_forearm_geom" type="capsule" size="0.04" fromto="0 0 0 0 0 0.2" rgba="0.5 0.9 0.5 1" mass="0.5"/>
          </body>
        </body>

        <!-- 左腿部 -->
        <body name="left_leg" pos="0.05 0 -0.2">
          <joint name="left_hip" type="hinge" axis="1 0 0" range="-1.57 1.57"/>
          <geom name="left_thigh" type="capsule" size="0.06" fromto="0 0 0 0 0 -0.3" rgba="0.9 0.9 0.5 1" mass="2"/>

          <body name="left_calf" pos="0 0 -0.3">
            <joint name="left_knee" type="hinge" axis="1 0 0" range="0 1.57"/>
            <geom name="left_calf_geom" type="capsule" size="0.05" fromto="0 0 0 0 0 -0.3" rgba="0.9 0.9 0.5 1" mass="1"/>
          </body>
        </body>

        <!-- 右腿部 -->
        <body name="right_leg" pos="-0.05 0 -0.2">
          <joint name="right_hip" type="hinge" axis="1 0 0" range="-1.57 1.57"/>
          <geom name="right_thigh" type="capsule" size="0.06" fromto="0 0 0 0 0 -0.3" rgba="0.9 0.9 0.5 1" mass="2"/>

          <body name="right_calf" pos="0 0 -0.3">
            <joint name="right_knee" type="hinge" axis="1 0 0" range="0 1.57"/>
            <geom name="right_calf_geom" type="capsule" size="0.05" fromto="0 0 0 0 0 -0.3" rgba="0.9 0.9 0.5 1" mass="1"/>
          </body>
        </body>
      </body>
    </body>
  </worldbody>

  <!-- 执行器定义（简化命名，与关节名一致） -->
  <actuator>
    <!-- 手臂关节电机 -->
    <motor name="left_shoulder" joint="left_shoulder" ctrlrange="-1.57 1.57" gear="20"/>
    <motor name="right_shoulder" joint="right_shoulder" ctrlrange="-1.57 1.57" gear="20"/>
    <motor name="left_elbow" joint="left_elbow" ctrlrange="-1.57 0" gear="15"/>
    <motor name="right_elbow" joint="right_elbow" ctrlrange="-1.57 0" gear="15"/>

    <!-- 腿部关节电机 -->
    <motor name="left_hip" joint="left_hip" ctrlrange="-1.57 1.57" gear="25"/>
    <motor name="right_hip" joint="right_hip" ctrlrange="-1.57 1.57" gear="25"/>
    <motor name="left_knee" joint="left_knee" ctrlrange="0 1.57" gear="20"/>
    <motor name="right_knee" joint="right_knee" ctrlrange="0 1.57" gear="20"/>

    <!-- 阻尼 -->
    <damping joint="left_shoulder" damping="0.5"/>
    <damping joint="right_shoulder" damping="0.5"/>
    <damping joint="left_elbow" damping="0.5"/>
    <damping joint="right_elbow" damping="0.5"/>
    <damping joint="left_hip" damping="0.8"/>
    <damping joint="right_hip" damping="0.8"/>
    <damping joint="left_knee" damping="0.8"/>
    <damping joint="right_knee" damping="0.8"/>
  </actuator>

  <!-- 固定骨盆防止倾倒 -->
  <equality>
    <weld body1="floor" body2="pelvis" solref="0.01 1" solimp="0.9 0.95 0.001"/>
  </equality>
</mujoco>