<mujoco model="simple_arm">
  <option timestep="0.01"/>
  <worldbody>
    <light pos="0 0 3" dir="0 0 -1"/>
    <geom name="floor" type="plane" size="5 5 0.1" rgba="0.9 0.9 0.9 1"/>
    <body name="arm_base" pos="0 0 0.1">
      <joint name="arm_joint" type="hinge" axis="0 1 0"/>
      <geom name="arm_link" type="capsule" fromto="0 0 0 0.5 0 0" size="0.05" rgba="0.5 0.5 0.5 1"/>
    </body>
  </worldbody>
  <actuator>
    <motor name="arm_motor" joint="arm_joint" gear="100"/>
  </actuator>
</mujoco>